[2025-08-14 21:03:09 +0000] [25122] [DEBUG] Current configuration:
  config: ./gunicorn.conf.py
  wsgi_app: None
  bind: ['unix:/var/www/member/tmp/gunicorn.sock']
  backlog: 2048
  workers: 3
  worker_class: sync
  threads: 1
  worker_connections: 1000
  max_requests: 0
  max_requests_jitter: 0
  timeout: 30
  graceful_timeout: 30
  keepalive: 2
  limit_request_line: 4094
  limit_request_fields: 100
  limit_request_field_size: 8190
  reload: False
  reload_engine: auto
  reload_extra_files: []
  spew: False
  check_config: False
  print_config: False
  preload_app: False
  sendfile: None
  reuse_port: False
  chdir: /var/www/member
  daemon: False
  raw_env: []
  pidfile: None
  worker_tmp_dir: None
  user: 999
  group: 988
  umask: 0
  initgroups: False
  tmp_upload_dir: None
  secure_scheme_headers: {'X-FORWARDED-PROTOCOL': 'ssl', 'X-FORWARDED-PROTO': 'https', 'X-FORWARDED-SSL': 'on'}
  forwarded_allow_ips: ['127.0.0.1', '::1']
  accesslog: None
  disable_redirect_access_to_syslog: False
  access_log_format: %(h)s %(l)s %(u)s %(t)s "%(r)s" %(s)s %(b)s "%(f)s" "%(a)s"
  errorlog: -
  loglevel: debug
  capture_output: False
  logger_class: gunicorn.glogging.Logger
  logconfig: None
  logconfig_dict: {}
  logconfig_json: None
  syslog_addr: udp://localhost:514
  syslog: False
  syslog_prefix: None
  syslog_facility: user
  enable_stdio_inheritance: False
  statsd_host: None
  dogstatsd_tags: 
  statsd_prefix: 
  proc_name: None
  default_proc_name: app:app
  pythonpath: None
  paste: None
  on_starting: <function OnStarting.on_starting at 0x74a4e4b43f60>
  on_reload: <function OnReload.on_reload at 0x74a4e4b600e0>
  when_ready: <function WhenReady.when_ready at 0x74a4e4b60220>
  pre_fork: <function Prefork.pre_fork at 0x74a4e4b60400>
  post_fork: <function Postfork.post_fork at 0x74a4e4b60540>
  post_worker_init: <function PostWorkerInit.post_worker_init at 0x74a4e4b60680>
  worker_int: <function WorkerInt.worker_int at 0x74a4e4b607c0>
  worker_abort: <function WorkerAbort.worker_abort at 0x74a4e4b60900>
  pre_exec: <function PreExec.pre_exec at 0x74a4e4b60a40>
  pre_request: <function PreRequest.pre_request at 0x74a4e4b60b80>
  post_request: <function PostRequest.post_request at 0x74a4e4b60c20>
  child_exit: <function ChildExit.child_exit at 0x74a4e4b60d60>
  worker_exit: <function WorkerExit.worker_exit at 0x74a4e4b60ea0>
  nworkers_changed: <function NumWorkersChanged.nworkers_changed at 0x74a4e4b60fe0>
  on_exit: <function OnExit.on_exit at 0x74a4e4b61120>
  ssl_context: <function NewSSLContext.ssl_context at 0x74a4e4b61300>
  proxy_protocol: False
  proxy_allow_ips: ['127.0.0.1', '::1']
  keyfile: None
  certfile: None
  ssl_version: 2
  cert_reqs: 0
  ca_certs: None
  suppress_ragged_eofs: True
  do_handshake_on_connect: False
  ciphers: None
  raw_paste_global_conf: []
  permit_obsolete_folding: False
  strip_header_spaces: False
  permit_unconventional_http_method: False
  permit_unconventional_http_version: False
  casefold_http_method: False
  forwarder_headers: ['SCRIPT_NAME', 'PATH_INFO']
  header_map: drop
[2025-08-14 21:03:09 +0000] [25122] [INFO] Starting gunicorn 23.0.0
[2025-08-14 21:03:09 +0000] [25122] [DEBUG] Arbiter booted
[2025-08-14 21:03:09 +0000] [25122] [INFO] Listening at: unix:/var/www/member/tmp/gunicorn.sock (25122)
[2025-08-14 21:03:09 +0000] [25122] [INFO] Using worker: sync
[2025-08-14 21:03:09 +0000] [25124] [INFO] Booting worker with pid: 25124
[2025-08-14 21:03:09 +0000] [25126] [INFO] Booting worker with pid: 25126
[2025-08-14 21:03:09 +0000] [25127] [INFO] Booting worker with pid: 25127
[2025-08-14 21:03:09 +0000] [25122] [DEBUG] 3 workers
[2025-08-14 21:03:10 +0000] [25124] [ERROR] Exception in worker process
Traceback (most recent call last):
  File "/var/www/member/venv/lib/python3.12/site-packages/gunicorn/arbiter.py", line 608, in spawn_worker
    worker.init_process()
  File "/var/www/member/venv/lib/python3.12/site-packages/gunicorn/workers/base.py", line 135, in init_process
    self.load_wsgi()
  File "/var/www/member/venv/lib/python3.12/site-packages/gunicorn/workers/base.py", line 147, in load_wsgi
    self.wsgi = self.app.wsgi()
                ^^^^^^^^^^^^^^^
  File "/var/www/member/venv/lib/python3.12/site-packages/gunicorn/app/base.py", line 66, in wsgi
    self.callable = self.load()
                    ^^^^^^^^^^^
  File "/var/www/member/venv/lib/python3.12/site-packages/gunicorn/app/wsgiapp.py", line 57, in load
    return self.load_wsgiapp()
           ^^^^^^^^^^^^^^^^^^^
  File "/var/www/member/venv/lib/python3.12/site-packages/gunicorn/app/wsgiapp.py", line 47, in load_wsgiapp
    return util.import_app(self.app_uri)
           ^^^^^^^^^^^^^^^^^^^^^^^^^^^^^
  File "/var/www/member/venv/lib/python3.12/site-packages/gunicorn/util.py", line 370, in import_app
    mod = importlib.import_module(module)
          ^^^^^^^^^^^^^^^^^^^^^^^^^^^^^^^
  File "/usr/lib/python3.12/importlib/__init__.py", line 90, in import_module
    return _bootstrap._gcd_import(name[level:], package, level)
           ^^^^^^^^^^^^^^^^^^^^^^^^^^^^^^^^^^^^^^^^^^^^^^^^^^^^
  File "<frozen importlib._bootstrap>", line 1387, in _gcd_import
  File "<frozen importlib._bootstrap>", line 1360, in _find_and_load
  File "<frozen importlib._bootstrap>", line 1331, in _find_and_load_unlocked
  File "<frozen importlib._bootstrap>", line 935, in _load_unlocked
  File "<frozen importlib._bootstrap_external>", line 995, in exec_module
  File "<frozen importlib._bootstrap>", line 488, in _call_with_frames_removed
  File "/var/www/member/app.py", line 22, in <module>
    app.register_blueprint(main_bp)
  File "/var/www/member/venv/lib/python3.12/site-packages/flask/sansio/scaffold.py", line 47, in wrapper_func
    return f(self, *args, **kwargs)
           ^^^^^^^^^^^^^^^^^^^^^^^^
  File "/var/www/member/venv/lib/python3.12/site-packages/flask/sansio/app.py", line 595, in register_blueprint
    blueprint.register(self, options)
  File "/var/www/member/venv/lib/python3.12/site-packages/flask/sansio/blueprints.py", line 335, in register
    deferred(state)
  File "/var/www/member/venv/lib/python3.12/site-packages/flask/sansio/blueprints.py", line 434, in <lambda>
    lambda s: s.add_url_rule(
              ^^^^^^^^^^^^^^^
  File "/var/www/member/venv/lib/python3.12/site-packages/flask/sansio/blueprints.py", line 110, in add_url_rule
    self.app.add_url_rule(
  File "/var/www/member/venv/lib/python3.12/site-packages/flask/sansio/scaffold.py", line 47, in wrapper_func
    return f(self, *args, **kwargs)
           ^^^^^^^^^^^^^^^^^^^^^^^^
  File "/var/www/member/venv/lib/python3.12/site-packages/flask/sansio/app.py", line 657, in add_url_rule
    raise AssertionError(
AssertionError: View function mapping is overwriting an existing endpoint function: main.decorated_function
[2025-08-14 21:03:10 +0000] [25124] [INFO] Worker exiting (pid: 25124)
[2025-08-14 21:03:10 +0000] [25126] [ERROR] Exception in worker process
Traceback (most recent call last):
  File "/var/www/member/venv/lib/python3.12/site-packages/gunicorn/arbiter.py", line 608, in spawn_worker
    worker.init_process()
  File "/var/www/member/venv/lib/python3.12/site-packages/gunicorn/workers/base.py", line 135, in init_process
    self.load_wsgi()
  File "/var/www/member/venv/lib/python3.12/site-packages/gunicorn/workers/base.py", line 147, in load_wsgi
    self.wsgi = self.app.wsgi()
                ^^^^^^^^^^^^^^^
  File "/var/www/member/venv/lib/python3.12/site-packages/gunicorn/app/base.py", line 66, in wsgi
    self.callable = self.load()
                    ^^^^^^^^^^^
  File "/var/www/member/venv/lib/python3.12/site-packages/gunicorn/app/wsgiapp.py", line 57, in load
    return self.load_wsgiapp()
           ^^^^^^^^^^^^^^^^^^^
  File "/var/www/member/venv/lib/python3.12/site-packages/gunicorn/app/wsgiapp.py", line 47, in load_wsgiapp
    return util.import_app(self.app_uri)
           ^^^^^^^^^^^^^^^^^^^^^^^^^^^^^
  File "/var/www/member/venv/lib/python3.12/site-packages/gunicorn/util.py", line 370, in import_app
    mod = importlib.import_module(module)
          ^^^^^^^^^^^^^^^^^^^^^^^^^^^^^^^
  File "/usr/lib/python3.12/importlib/__init__.py", line 90, in import_module
    return _bootstrap._gcd_import(name[level:], package, level)
           ^^^^^^^^^^^^^^^^^^^^^^^^^^^^^^^^^^^^^^^^^^^^^^^^^^^^
  File "<frozen importlib._bootstrap>", line 1387, in _gcd_import
  File "<frozen importlib._bootstrap>", line 1360, in _find_and_load
  File "<frozen importlib._bootstrap>", line 1331, in _find_and_load_unlocked
  File "<frozen importlib._bootstrap>", line 935, in _load_unlocked
  File "<frozen importlib._bootstrap_external>", line 995, in exec_module
  File "<frozen importlib._bootstrap>", line 488, in _call_with_frames_removed
  File "/var/www/member/app.py", line 22, in <module>
    app.register_blueprint(main_bp)
  File "/var/www/member/venv/lib/python3.12/site-packages/flask/sansio/scaffold.py", line 47, in wrapper_func
    return f(self, *args, **kwargs)
           ^^^^^^^^^^^^^^^^^^^^^^^^
  File "/var/www/member/venv/lib/python3.12/site-packages/flask/sansio/app.py", line 595, in register_blueprint
    blueprint.register(self, options)
  File "/var/www/member/venv/lib/python3.12/site-packages/flask/sansio/blueprints.py", line 335, in register
    deferred(state)
  File "/var/www/member/venv/lib/python3.12/site-packages/flask/sansio/blueprints.py", line 434, in <lambda>
    lambda s: s.add_url_rule(
              ^^^^^^^^^^^^^^^
  File "/var/www/member/venv/lib/python3.12/site-packages/flask/sansio/blueprints.py", line 110, in add_url_rule
    self.app.add_url_rule(
  File "/var/www/member/venv/lib/python3.12/site-packages/flask/sansio/scaffold.py", line 47, in wrapper_func
    return f(self, *args, **kwargs)
           ^^^^^^^^^^^^^^^^^^^^^^^^
  File "/var/www/member/venv/lib/python3.12/site-packages/flask/sansio/app.py", line 657, in add_url_rule
    raise AssertionError(
AssertionError: View function mapping is overwriting an existing endpoint function: main.decorated_function
[2025-08-14 21:03:10 +0000] [25126] [INFO] Worker exiting (pid: 25126)
[2025-08-14 21:03:10 +0000] [25122] [ERROR] Worker (pid:25124) exited with code 3
[2025-08-14 21:03:10 +0000] [25122] [ERROR] Worker (pid:25126) was sent SIGTERM!
[2025-08-14 21:03:10 +0000] [25127] [ERROR] Exception in worker process
Traceback (most recent call last):
  File "/var/www/member/venv/lib/python3.12/site-packages/gunicorn/arbiter.py", line 608, in spawn_worker
    worker.init_process()
  File "/var/www/member/venv/lib/python3.12/site-packages/gunicorn/workers/base.py", line 135, in init_process
    self.load_wsgi()
  File "/var/www/member/venv/lib/python3.12/site-packages/gunicorn/workers/base.py", line 147, in load_wsgi
    self.wsgi = self.app.wsgi()
                ^^^^^^^^^^^^^^^
  File "/var/www/member/venv/lib/python3.12/site-packages/gunicorn/app/base.py", line 66, in wsgi
    self.callable = self.load()
                    ^^^^^^^^^^^
  File "/var/www/member/venv/lib/python3.12/site-packages/gunicorn/app/wsgiapp.py", line 57, in load
    return self.load_wsgiapp()
           ^^^^^^^^^^^^^^^^^^^
  File "/var/www/member/venv/lib/python3.12/site-packages/gunicorn/app/wsgiapp.py", line 47, in load_wsgiapp
    return util.import_app(self.app_uri)
           ^^^^^^^^^^^^^^^^^^^^^^^^^^^^^
  File "/var/www/member/venv/lib/python3.12/site-packages/gunicorn/util.py", line 370, in import_app
    mod = importlib.import_module(module)
          ^^^^^^^^^^^^^^^^^^^^^^^^^^^^^^^
  File "/usr/lib/python3.12/importlib/__init__.py", line 90, in import_module
    return _bootstrap._gcd_import(name[level:], package, level)
           ^^^^^^^^^^^^^^^^^^^^^^^^^^^^^^^^^^^^^^^^^^^^^^^^^^^^
  File "<frozen importlib._bootstrap>", line 1387, in _gcd_import
  File "<frozen importlib._bootstrap>", line 1360, in _find_and_load
  File "<frozen importlib._bootstrap>", line 1331, in _find_and_load_unlocked
  File "<frozen importlib._bootstrap>", line 935, in _load_unlocked
  File "<frozen importlib._bootstrap_external>", line 995, in exec_module
  File "<frozen importlib._bootstrap>", line 488, in _call_with_frames_removed
  File "/var/www/member/app.py", line 22, in <module>
    app.register_blueprint(main_bp)
  File "/var/www/member/venv/lib/python3.12/site-packages/flask/sansio/scaffold.py", line 47, in wrapper_func
    return f(self, *args, **kwargs)
           ^^^^^^^^^^^^^^^^^^^^^^^^
  File "/var/www/member/venv/lib/python3.12/site-packages/flask/sansio/app.py", line 595, in register_blueprint
    blueprint.register(self, options)
  File "/var/www/member/venv/lib/python3.12/site-packages/flask/sansio/blueprints.py", line 335, in register
    deferred(state)
  File "/var/www/member/venv/lib/python3.12/site-packages/flask/sansio/blueprints.py", line 434, in <lambda>
    lambda s: s.add_url_rule(
              ^^^^^^^^^^^^^^^
  File "/var/www/member/venv/lib/python3.12/site-packages/flask/sansio/blueprints.py", line 110, in add_url_rule
    self.app.add_url_rule(
  File "/var/www/member/venv/lib/python3.12/site-packages/flask/sansio/scaffold.py", line 47, in wrapper_func
    return f(self, *args, **kwargs)
           ^^^^^^^^^^^^^^^^^^^^^^^^
  File "/var/www/member/venv/lib/python3.12/site-packages/flask/sansio/app.py", line 657, in add_url_rule
    raise AssertionError(
AssertionError: View function mapping is overwriting an existing endpoint function: main.decorated_function
[2025-08-14 21:03:10 +0000] [25127] [INFO] Worker exiting (pid: 25127)
[2025-08-14 21:03:10 +0000] [25122] [ERROR] Worker (pid:25127) exited with code 3
Traceback (most recent call last):
  File "/var/www/member/venv/lib/python3.12/site-packages/gunicorn/arbiter.py", line 208, in run
    self.sleep()
  File "/var/www/member/venv/lib/python3.12/site-packages/gunicorn/arbiter.py", line 359, in sleep
    ready = select.select([self.PIPE[0]], [], [], 1.0)
            ^^^^^^^^^^^^^^^^^^^^^^^^^^^^^^^^^^^^^^^^^^
  File "/var/www/member/venv/lib/python3.12/site-packages/gunicorn/arbiter.py", line 241, in handle_chld
    self.reap_workers()
  File "/var/www/member/venv/lib/python3.12/site-packages/gunicorn/arbiter.py", line 529, in reap_workers
    raise HaltServer(reason, self.WORKER_BOOT_ERROR)
gunicorn.errors.HaltServer: <HaltServer 'Worker failed to boot.' 3>

During handling of the above exception, another exception occurred:

Traceback (most recent call last):
  File "/var/www/member/venv/bin/gunicorn", line 8, in <module>
    sys.exit(run())
             ^^^^^
  File "/var/www/member/venv/lib/python3.12/site-packages/gunicorn/app/wsgiapp.py", line 66, in run
    WSGIApplication("%(prog)s [OPTIONS] [APP_MODULE]", prog=prog).run()
  File "/var/www/member/venv/lib/python3.12/site-packages/gunicorn/app/base.py", line 235, in run
    super().run()
  File "/var/www/member/venv/lib/python3.12/site-packages/gunicorn/app/base.py", line 71, in run
    Arbiter(self).run()
  File "/var/www/member/venv/lib/python3.12/site-packages/gunicorn/arbiter.py", line 228, in run
    self.halt(reason=inst.reason, exit_status=inst.exit_status)
  File "/var/www/member/venv/lib/python3.12/site-packages/gunicorn/arbiter.py", line 341, in halt
    self.stop()
  File "/var/www/member/venv/lib/python3.12/site-packages/gunicorn/arbiter.py", line 395, in stop
    time.sleep(0.1)
  File "/var/www/member/venv/lib/python3.12/site-packages/gunicorn/arbiter.py", line 241, in handle_chld
    self.reap_workers()
  File "/var/www/member/venv/lib/python3.12/site-packages/gunicorn/arbiter.py", line 529, in reap_workers
    raise HaltServer(reason, self.WORKER_BOOT_ERROR)
gunicorn.errors.HaltServer: <HaltServer 'Worker failed to boot.' 3>
